2025-06-06 10:00:00,800 ERROR scheduler Exception in Enqueue Events for Site erpnext.localhost
Traceback (most recent call last):
  File "/home/valea/Documents/Eval/ERPNext_Existant/env/lib/python3.12/site-packages/pymysql/connections.py", line 649, in connect
    sock = socket.create_connection(
           ^^^^^^^^^^^^^^^^^^^^^^^^^
  File "/usr/lib/python3.12/socket.py", line 852, in create_connection
    raise exceptions[0]
  File "/usr/lib/python3.12/socket.py", line 837, in create_connection
    sock.connect(sa)
ConnectionRefusedError: [Errno 111] Connection refused

During handling of the above exception, another exception occurred:

Traceback (most recent call last):
  File "/home/valea/Documents/Eval/ERPNext_Existant/apps/frappe/frappe/utils/scheduler.py", line 117, in enqueue_events_for_site
    if is_scheduler_inactive():
       ^^^^^^^^^^^^^^^^^^^^^^^
  File "/home/valea/Documents/Eval/ERPNext_Existant/apps/frappe/frappe/utils/scheduler.py", line 161, in is_scheduler_inactive
    if is_scheduler_disabled(verbose=verbose):
       ^^^^^^^^^^^^^^^^^^^^^^^^^^^^^^^^^^^^^^
  File "/home/valea/Documents/Eval/ERPNext_Existant/apps/frappe/frappe/utils/scheduler.py", line 174, in is_scheduler_disabled
    frappe.db.get_single_value("System Settings", "enable_scheduler")
  File "/home/valea/Documents/Eval/ERPNext_Existant/apps/frappe/frappe/database/database.py", line 884, in get_single_value
    ).run()
      ^^^^^
  File "/home/valea/Documents/Eval/ERPNext_Existant/apps/frappe/frappe/query_builder/utils.py", line 85, in execute_query
    result = frappe.db.sql(query, params, *args, **kwargs)  # nosemgrep
             ^^^^^^^^^^^^^^^^^^^^^^^^^^^^^^^^^^^^^^^^^^^^^
  File "/home/valea/Documents/Eval/ERPNext_Existant/apps/frappe/frappe/database/database.py", line 237, in sql
    self.connect()
  File "/home/valea/Documents/Eval/ERPNext_Existant/apps/frappe/frappe/database/database.py", line 135, in connect
    self.get_connection()
  File "/home/valea/Documents/Eval/ERPNext_Existant/apps/frappe/frappe/database/mariadb/database.py", line 106, in get_connection
    conn = self._get_connection()
           ^^^^^^^^^^^^^^^^^^^^^^
  File "/home/valea/Documents/Eval/ERPNext_Existant/apps/frappe/frappe/database/mariadb/database.py", line 112, in _get_connection
    return self.create_connection()
           ^^^^^^^^^^^^^^^^^^^^^^^^
  File "/home/valea/Documents/Eval/ERPNext_Existant/apps/frappe/frappe/database/mariadb/database.py", line 115, in create_connection
    return pymysql.connect(**self.get_connection_settings())
           ^^^^^^^^^^^^^^^^^^^^^^^^^^^^^^^^^^^^^^^^^^^^^^^^^
  File "/home/valea/Documents/Eval/ERPNext_Existant/env/lib/python3.12/site-packages/pymysql/connections.py", line 361, in __init__
    self.connect()
  File "/home/valea/Documents/Eval/ERPNext_Existant/env/lib/python3.12/site-packages/pymysql/connections.py", line 716, in connect
    raise exc
pymysql.err.OperationalError: (2003, "Can't connect to MySQL server on '127.0.0.1' ([Errno 111] Connection refused)")
